<?xml version="1.0" encoding="utf-8"?>
<!-- This URDF was automatically created by SolidWorks to URDF Exporter! Originally created by Stephen Brawner (brawner@gmail.com) 
     Commit Version: 1.6.0-4-g7f85cfe  Build Version: 1.6.7995.38578
     For more information, please see http://wiki.ros.org/sw_urdf_exporter -->
<robot
  name="giang">
  <link
    name="base_link">
    <inertial>
      <origin
        xyz="-0.00407730719910837 -0.0189070990166384 0.0486758718899547"
        rpy="0 0 0" />
      <mass
        value="1.61371686593512" />
      <inertia
        ixx="0.00190294205026824"
        ixy="-0.000114075013577605"
        ixz="-3.93773068625565E-05"
        iyy="0.00195033809154291"
        iyz="-0.000339835287344812"
        izz="0.00302612684815536" />
    </inertial>
    <visual>
      <origin
        xyz="0 0 0"
        rpy="0 0 0" />
      <geometry>
        <mesh
          filename="package://giang/meshes/base_link.STL" />
      </geometry>
      <material
        name="">
        <color
          rgba="0.650980392156863 0.619607843137255 0.588235294117647 1" />
      </material>
    </visual>
    <collision>
      <origin
        xyz="0 0 0"
        rpy="0 0 0" />
      <geometry>
        <mesh
          filename="package://giang/meshes/base_link.STL" />
      </geometry>
    </collision>
  </link>
  <link
    name="traicam">
    <inertial>
      <origin
        xyz="1.11127516957965E-06 0.00454255329124797 0.013285762321554"
        rpy="0 0 0" />
      <mass
        value="0.216553757587495" />
      <inertia
        ixx="4.5330321268905E-05"
        ixy="2.24020791294186E-09"
        ixz="1.23633240403192E-09"
        iyy="4.91826515535104E-05"
        iyz="1.12578799582933E-05"
        izz="7.82689182650466E-05" />
    </inertial>
    <visual>
      <origin
        xyz="0 0 0"
        rpy="0 0 0" />
      <geometry>
        <mesh
          filename="package://giang/meshes/traicam.STL" />
      </geometry>
      <material
        name="">
        <color
          rgba="0.294117647058824 0.294117647058824 0.294117647058824 1" />
      </material>
    </visual>
    <collision>
      <origin
        xyz="0 0 0"
        rpy="0 0 0" />
      <geometry>
        <mesh
          filename="package://giang/meshes/traicam.STL" />
      </geometry>
    </collision>
  </link>
  <joint
    name="j_traicam"
    type="continuous">
    <origin
      xyz="0.07224 -0.12222 -0.061203"
      rpy="-1.6753 -0.96906 -2.2668" />
    <parent
      link="base_link" />
    <child
      link="traicam" />
    <axis
      xyz="0 0.32332 0.94629" />
  </joint>
  <link
    name="phaicam">
    <inertial>
      <origin
        xyz="-2.85432592229268E-06 1.19242671126063E-06 -0.0297744682764462"
        rpy="0 0 0" />
      <mass
        value="0.2165537429782" />
      <inertia
        ixx="4.53336998537909E-05"
        ixy="-2.31768775303798E-09"
        ixz="-4.78882419731045E-09"
        iyy="4.53310330222237E-05"
        iyz="2.76844729913603E-09"
        izz="8.21171557673177E-05" />
    </inertial>
    <visual>
      <origin
        xyz="0 0 0"
        rpy="0 0 0" />
      <geometry>
        <mesh
          filename="package://giang/meshes/phaicam.STL" />
      </geometry>
      <material
        name="">
        <color
          rgba="0.501960784313725 0.501960784313725 0.501960784313725 1" />
      </material>
    </visual>
    <collision>
      <origin
        xyz="0 0 0"
        rpy="0 0 0" />
      <geometry>
        <mesh
          filename="package://giang/meshes/phaicam.STL" />
      </geometry>
    </collision>
  </link>
  <joint
    name="j_phaicam"
    type="continuous">
    <origin
      xyz="0.10376 0.1673 0.020053"
      rpy="-0.79655 -1.2374 -1.324" />
    <parent
      link="base_link" />
    <child
      link="phaicam" />
    <axis
      xyz="0 0 1" />
  </joint>
  <link
    name="saucam">
    <inertial>
      <origin
        xyz="9.02574320837957E-10 3.2498472427589E-06 0.0768266214061987"
        rpy="0 0 0" />
      <mass
        value="0.216553751062434" />
      <inertia
        ixx="4.53296981278038E-05"
        ixy="1.37634899950636E-12"
        ixz="3.56525606834499E-12"
        iyy="4.53350436706611E-05"
        iyz="5.53193597537422E-09"
        izz="8.21171642070257E-05" />
    </inertial>
    <visual>
      <origin
        xyz="0 0 0"
        rpy="0 0 0" />
      <geometry>
        <mesh
          filename="package://giang/meshes/saucam.STL" />
      </geometry>
      <material
        name="">
        <color
          rgba="0.752941176470588 0.752941176470588 0.752941176470588 1" />
      </material>
    </visual>
    <collision>
      <origin
        xyz="0 0 0"
        rpy="0 0 0" />
      <geometry>
        <mesh
          filename="package://giang/meshes/saucam.STL" />
      </geometry>
    </collision>
  </link>
  <joint
    name="j_saucam"
    type="continuous">
    <origin
      xyz="-0.089592 0.0095916 -0.024209"
      rpy="-1.5614 -0.55681 1.5374" />
    <parent
      link="base_link" />
    <child
      link="saucam" />
    <axis
      xyz="0 0 1" />
  </joint>
  <link
    name="cam">
    <inertial>
      <origin
        xyz="-0.00549159067882473 0.000142782093136729 0.00542399688213652"
        rpy="0 0 0" />
      <mass
        value="0.00106909376084806" />
      <inertia
        ixx="1.96245738762131E-08"
        ixy="-6.82424005356248E-24"
        ixz="-8.32350491381484E-24"
        iyy="1.96245738762131E-08"
        iyz="-3.01920923581855E-23"
        izz="1.6906568016913E-08" />
    </inertial>
    <visual>
      <origin
        xyz="0 0 0"
        rpy="0 0 0" />
      <geometry>
        <mesh
          filename="package://giang/meshes/cam.STL" />
      </geometry>
      <material
        name="">
        <color
          rgba="0.792156862745098 0.819607843137255 0.933333333333333 1" />
      </material>
    </visual>
    <collision>
      <origin
        xyz="0 0 0"
        rpy="0 0 0" />
      <geometry>
        <mesh
          filename="package://giang/meshes/cam.STL" />
      </geometry>
    </collision>
  </link>
  <joint
    name="j_cam"
    type="fixed">
    <origin
      xyz="0.04771 -0.0043367 0.0096798"
      rpy="-1.5708 -1.2972 -1.5708" />
    <parent
      link="base_link" />
    <child
      link="cam" />
    <axis
      xyz="0 0 0" />
  </joint>
  <link
    name="lidar">
    <inertial>
      <origin
        xyz="-0.0119894544017546 0.0147708495509629 -5.08714633240537E-06"
        rpy="0 0 0" />
      <mass
        value="1.11523596286073" />
      <inertia
        ixx="0.000449679095584544"
        ixy="2.81363257557769E-05"
        ixz="-1.24593204258014E-08"
        iyy="0.000772785451493485"
        iyz="8.98983080473076E-08"
        izz="0.000555359086215568" />
    </inertial>
    <visual>
      <origin
        xyz="0 0 0"
        rpy="0 0 0" />
      <geometry>
        <mesh
          filename="package://giang/meshes/lidar.STL" />
      </geometry>
      <material
        name="">
        <color
          rgba="0.792156862745098 0.819607843137255 0.933333333333333 1" />
      </material>
    </visual>
    <collision>
      <origin
        xyz="0 0 0"
        rpy="0 0 0" />
      <geometry>
        <mesh
          filename="package://giang/meshes/lidar.STL" />
      </geometry>
    </collision>
  </link>
  <joint
    name="j_lidar"
    type="fixed">
    <origin
      xyz="-0.078086 0.011521 0.0063493"
      rpy="1.8164 0.12193 -0.45181" />
    <parent
      link="base_link" />
    <child
      link="lidar" />
    <axis
      xyz="0 0 0" />
  </joint>
  <link
    name="tt1">
    <inertial>
      <origin
        xyz="5.55111512312578E-16 -1.41553435639707E-15 0.0817027065570053"
        rpy="0 0 0" />
      <mass
        value="0.273318560862312" />
      <inertia
        ixx="0.0005132055655918"
        ixy="-2.71050543121376E-20"
        ixz="-4.36221967835965E-20"
        iyy="0.000513205565591801"
        iyz="2.05829006182795E-19"
        izz="8.96532003518189E-05" />
    </inertial>
    <visual>
      <origin
        xyz="0 0 0"
        rpy="0 0 0" />
      <geometry>
        <mesh
          filename="package://giang/meshes/tt1.STL" />
      </geometry>
      <material
        name="">
        <color
          rgba="0.792156862745098 0.819607843137255 0.933333333333333 1" />
      </material>
    </visual>
    <collision>
      <origin
        xyz="0 0 0"
        rpy="0 0 0" />
      <geometry>
        <mesh
          filename="package://giang/meshes/tt1.STL" />
      </geometry>
    </collision>
  </link>
  <joint
    name="j_tt1"
    type="prismatic">
    <origin
      xyz="0 6.0234E-05 -0.00021462"
      rpy="-0.27361 0.0020889 -3.1341" />
    <parent
      link="base_link" />
    <child
      link="tt1" />
    <axis
      xyz="0 0 1" />
    <limit
      lower="0"
      upper="0"
      effort="0"
      velocity="0" />
  </joint>
  <link
    name="tt2">
    <inertial>
      <origin
        xyz="5.55111512312578E-17 2.22044604925031E-16 -0.0558509099130727"
        rpy="0 0 0" />
      <mass
        value="0.0706858347057703" />
      <inertia
        ixx="6.28809404570082E-05"
        ixy="3.17637355220363E-22"
        ixz="-3.61047793767146E-20"
        iyy="6.28809404570082E-05"
        iyz="1.75282880522437E-19"
        izz="7.95215640439916E-06" />
    </inertial>
    <visual>
      <origin
        xyz="0 0 0"
        rpy="0 0 0" />
      <geometry>
        <mesh
          filename="package://giang/meshes/tt2.STL" />
      </geometry>
      <material
        name="">
        <color
          rgba="0.792156862745098 0.819607843137255 0.933333333333333 1" />
      </material>
    </visual>
    <collision>
      <origin
        xyz="0 0 0"
        rpy="0 0 0" />
      <geometry>
        <mesh
          filename="package://giang/meshes/tt2.STL" />
      </geometry>
    </collision>
  </link>
  <joint
    name="j_tt2"
    type="prismatic">
    <origin
      xyz="-0.0529676319958768 -0.106682839638125 0.138135732675067"
      rpy="-1.35924840820937 0.00504628222108553 -0.698372509057435" />
    <parent
      link="base_link" />
    <child
      link="tt2" />
    <axis
      xyz="0 0 1" />
    <limit
      lower="0"
      upper="0"
      effort="0"
      velocity="0" />
  </joint>
</robot>